{
  "@type": "job",
  "@href": "/v3/job/276055846",
  "@representation": "standard",
  "@permissions": {
    "read": true,
    "delete_log": false,
    "debug": false,
    "cancel": false,
    "restart": false
  },
  "id": 276055846,
  "allow_failure": false,
  "number": "25874.6",
  "state": "passed",
  "started_at": "2017-09-15T21:20:21Z",
  "finished_at": "2017-09-15T21:43:09Z",
  "build": {
    "@type": "build",
    "@href": "/v3/build/276055834",
    "@representation": "minimal",
    "id": 276055834,
    "number": "25874",
    "state": "failed",
    "duration": 18319,
    "event_type": "pull_request",
    "previous_state": "errored",
    "pull_request_title": "Add async retry to RetryDriver",
    "pull_request_number": 8464,
    "started_at": "2017-09-15T21:19:26Z",
    "finished_at": "2017-09-15T22:03:34Z",
    "private": false
  },
  "queue": "builds.gce",
  "repository": {
    "@type": "repository",
    "@href": "/v3/repo/1504827",
    "@representation": "minimal",
    "id": 1504827,
    "name": "presto",
    "slug": "prestodb/presto"
  },
  "commit": {
    "@type": "commit",
    "@representation": "minimal",
    "id": 80440113,
    "sha": "473f728b26d79dec4a271ba8e56c589d40737e58",
    "ref": "refs/pull/8464/merge",
    "message": "Retry async thrift failure\n\nPreviously there was no retry when an async thrift call fails after\nits future is returned.\n\nTo solve this, we wrap the returned future\nIt will automatically renew itself on an async exception based on\nour retry policy.",
    "compare_url": "https://github.com/prestodb/presto/pull/8464",
    "committed_at": "2017-09-15T20:45:29Z"
  },
  "owner": {
    "@type": "organization",
    "@href": "/v3/org/61142",
    "@representation": "minimal",
    "id": 61142,
    "login": "prestodb"
  },
  "stage": null,
  "created_at": "2017-09-15T20:52:06.186Z",
  "updated_at": "2018-06-03T03:20:14.738Z",
  "private": false
}